<?xml version="1.0" ?>
<robot name="mbot">

    <link name="base_link">
        <visual>
            <origin xyz=" 0 0 0" rpy="0 0 0" />
            <geometry>
                <cylinder length="0.1" radius="0.175"/>
            </geometry>
            <material name="white">
                <color rgba="1 1 1 1"/>
            </material>
        </visual>
    </link>

    <joint name="left_wheel_joint" type="continuous">
        <origin xyz="-0.09 -0.10 -0.05" rpy="0 1.57 0"/>
        <parent link="base_link"/>
        <child link="left_wheel_link"/>
        <axis xyz="0 1 0"/>
    </joint>

    <link name="left_wheel_link">
        <visual>
            <origin xyz="0 0 0" rpy="0 0 0" />
            <geometry>
                <cylinder radius="0.03" length = "0.02"/>
            </geometry>
            <material name="black">
                <color rgba="0 0 0 1"/>
            </material>
        </visual>
    </link>

    <joint name="right_wheel_joint" type="continuous">
        <origin xyz="0.09 -0.10 -0.05" rpy="0 1.57 0"/>
        <parent link="base_link"/>
        <child link="right_wheel_link"/>
        <axis xyz="0 1 0"/>
    </joint>

    <link name="right_wheel_link">
        <visual>
            <origin xyz="0 0 0" rpy="0 0 0" />
            <geometry>
                <cylinder radius="0.03" length = "0.02"/>
            </geometry>
            <material name="black">
                <color rgba="0 0 0 1"/>
            </material>
        </visual>
    </link>

    <joint name="middle_wheel_joint" type="continuous">
        <origin xyz="0.00 0.12 -0.06" rpy="0 1.57 0"/>
        <parent link="base_link"/>
        <child link="middle_wheel_link"/>
        <axis xyz="0 1 0"/>
    </joint>

    <link name="middle_wheel_link">
        <visual>
            <origin xyz="0 0 0" rpy="0 0 0" />
            <geometry>
                <cylinder radius="0.02" length = "0.01"/>
            </geometry>
            <material name="black">
                <color rgba="0 0 0 1"/>
            </material>
        </visual>
    </link>

    <link name="kinect_link">
        <visual>
            <origin xyz="0 0 0" rpy="0 0 3.14"/>
            <geometry>
                <mesh filename="package://mbot_description/meshes/kinect.dae" />
            </geometry>
        </visual>
    </link>

    <joint name="kinect_joint" type="fixed">
        <origin xyz="0 0 0.08" rpy="0 0 0"/>
        <parent link="base_link"/>
        <child link="kinect_link"/>
    </joint>

    <link name="camera_link">
        <visual>
            <origin xyz=" 0 0 0 " rpy="0 0 0" />
            <geometry>
                <box size="0.04 0.04 0.04" />
            </geometry>
            <material name="red">
                <color rgba="1 0 0 0.95"/>
            </material>
        </visual>
    </link>

    <joint name="camera_joint" type="fixed">
        <origin xyz="0.05 0.1 0.06" rpy="0 0 0"/>
        <parent link="base_link"/>
        <child link="camera_link"/>
    </joint>

    <link name="laser_link">
		<visual>
			<origin xyz=" 0 0 0 " rpy="0 0 0" />
			<geometry>
				<cylinder length="0.05" radius="0.02"/>
			</geometry>
			<material name="blue">
                <color rgba="0 0 1 0.95"/>
            </material>
		</visual>
    </link>

    <joint name="laser_joint" type="fixed">
        <origin xyz="-0.05 0.1 0.06" rpy="0 0 0"/>
        <parent link="base_link"/>
        <child link="laser_link"/>
    </joint>
    
</robot>